#usda 1.0
(
    defaultPrim = "vehicle"
    metersPerUnit = 1
    upAxis = "Z"
)

def Xform "vehicle" (
    apiSchemas = ["PhysicsArticulationRootAPI", "PhysxArticulationAPI"]
)
{
    bool physxArticulation:enabledSelfCollisions = 0
    int physxArticulation:solverPositionIterationCount = 128
    int physxArticulation:solverVelocityIterationCount = 32
    float3 xformOp:rotateXYZ = (0, 0, 0)
    float3 xformOp:scale = (1, 1, 1)
    double3 xformOp:translate = (0, 0, 0)
    uniform token[] xformOpOrder = ["xformOp:translate", "xformOp:rotateXYZ", "xformOp:scale"]

    def Xform "body" (
        apiSchemas = ["PhysicsMassAPI", "PhysicsRigidBodyAPI", "PhysxRigidBodyAPI"]
    )
    {
        point3f physics:centerOfMass = (0, 0, 0)
        float3 physics:diagonalInertia = (12.5, 12.5, 25)
        bool physics:kinematicEnabled = 0
        float physics:mass = 100
        bool physics:rigidBodyEnabled = 1
        float physxRigidBody:angularDamping = 0
        float physxRigidBody:maxAngularVelocity = 10000
        float physxRigidBody:maxContactImpulse = 0.1
        quatf xformOp:orient = (1, 0, 0, 0)
        double3 xformOp:scale = (1, 1, 1)
        float3 xformOp:translate = (0, 0, 0)
        uniform token[] xformOpOrder = ["xformOp:translate", "xformOp:orient", "xformOp:scale"]

        def Cube "collision" (
            apiSchemas = ["PhysicsCollisionAPI"]
        )
        {
            float3[] extent = [(-0.5, -0.5, -0.5), (0.5, 0.5, 0.5)]
            bool physics:collisionEnabled = 1
            double size = 1
            token visibility = "invisible"
            quatf xformOp:orient = (1, 0, 0, 0)
            double3 xformOp:scale = (1, 0.9, 0.5)
            double3 xformOp:translate = (0, 0, 0.05)
            uniform token[] xformOpOrder = ["xformOp:translate", "xformOp:orient", "xformOp:scale"]
        }
    }

    def Xform "arm_geo" (
        prepend references = @./arm.usda@
    )
    {
        quatf xformOp:orient = (1, 0, 0, 0)
        double3 xformOp:scale = (1, 1, 1)
        double3 xformOp:translate = (0, 0, 0)
        uniform token[] xformOpOrder = ["xformOp:translate", "xformOp:orient", "xformOp:scale"]

        over "Geometry"
        {
            over "base_link" (
                delete apiSchemas = ["PhysicsArticulationRootAPI", "PhysxArticulationAPI", "NewtonArticulationRootAPI"]
            )
            {
            }
        }
    }

    def PhysicsFixedJoint "arm_mount"
    {
        rel physics:body0 = </vehicle/body>
        rel physics:body1 = </vehicle/arm_geo/Geometry/base_link>
        point3f physics:localPos0 = (0, 0, 0)
        point3f physics:localPos1 = (0, 0, 0)
        quatf physics:localRot0 = (1, 0, 0, 0)
        quatf physics:localRot1 = (1, 0, 0, 0)
    }

    def Xform "rotor0" (
        apiSchemas = ["PhysicsMassAPI", "PhysicsRigidBodyAPI", "PhysxRigidBodyAPI"]
    )
    {
        float3 physics:diagonalInertia = (0.00000975, 0.000273, 0.000274)
        bool physics:kinematicEnabled = 0
        float physics:mass = 0.05
        bool physics:rigidBodyEnabled = 1
        float physxRigidBody:angularDamping = 0
        float physxRigidBody:maxAngularVelocity = 10000
        float physxRigidBody:maxContactImpulse = 0.1
        quatf xformOp:orient = (1, 0, 0, 0)
        double3 xformOp:scale = (1, 1, 1)
        float3 xformOp:translate = (0.508, 0, 0.03)
        uniform token[] xformOpOrder = ["xformOp:translate", "xformOp:orient", "xformOp:scale"]

        def Xform "propeller" (
            prepend references = @./propeller.usd@
        )
        {
            double3 xformOp:scale = (3, 3, 3)
            uniform token[] xformOpOrder = ["xformOp:translate", "xformOp:orient", "xformOp:scale"]
        }

        def PhysicsRevoluteJoint "rotor_1"
        {
            uniform token physics:axis = "Z"
            rel physics:body0 = </vehicle/body>
            rel physics:body1 = </vehicle/rotor0>
            point3f physics:localPos0 = (0.508, 0, 0.03)
            point3f physics:localPos1 = (0, 0, 0)
        }
    }

    def Xform "rotor1" (
        apiSchemas = ["PhysicsMassAPI", "PhysicsRigidBodyAPI", "PhysxRigidBodyAPI"]
    )
    {
        float3 physics:diagonalInertia = (0.00000975, 0.000273, 0.000274)
        bool physics:kinematicEnabled = 0
        float physics:mass = 0.05
        bool physics:rigidBodyEnabled = 1
        float physxRigidBody:angularDamping = 0
        float physxRigidBody:maxAngularVelocity = 10000
        float physxRigidBody:maxContactImpulse = 0.1
        quatf xformOp:orient = (1, 0, 0, 0)
        double3 xformOp:scale = (1, 1, 1)
        float3 xformOp:translate = (0.254, 0.4399, 0.03)
        uniform token[] xformOpOrder = ["xformOp:translate", "xformOp:orient", "xformOp:scale"]

        def Xform "propeller" (
            prepend references = @./propeller.usd@
        )
        {
            double3 xformOp:scale = (3, 3, 3)
            uniform token[] xformOpOrder = ["xformOp:translate", "xformOp:orient", "xformOp:scale"]
        }

        def PhysicsRevoluteJoint "rotor_2"
        {
            uniform token physics:axis = "Z"
            rel physics:body0 = </vehicle/body>
            rel physics:body1 = </vehicle/rotor1>
            point3f physics:localPos0 = (0.254, 0.4399, 0.03)
            point3f physics:localPos1 = (0, 0, 0)
        }
    }

    def Xform "rotor2" (
        apiSchemas = ["PhysicsMassAPI", "PhysicsRigidBodyAPI", "PhysxRigidBodyAPI"]
    )
    {
        float3 physics:diagonalInertia = (0.00000975, 0.000273, 0.000274)
        bool physics:kinematicEnabled = 0
        float physics:mass = 0.05
        bool physics:rigidBodyEnabled = 1
        float physxRigidBody:angularDamping = 0
        float physxRigidBody:maxAngularVelocity = 10000
        float physxRigidBody:maxContactImpulse = 0.1
        quatf xformOp:orient = (1, 0, 0, 0)
        double3 xformOp:scale = (1, 1, 1)
        float3 xformOp:translate = (-0.254, 0.4399, 0.03)
        uniform token[] xformOpOrder = ["xformOp:translate", "xformOp:orient", "xformOp:scale"]

        def Xform "propeller" (
            prepend references = @./propeller.usd@
        )
        {
            double3 xformOp:scale = (3, 3, 3)
            uniform token[] xformOpOrder = ["xformOp:translate", "xformOp:orient", "xformOp:scale"]
        }

        def PhysicsRevoluteJoint "rotor_3"
        {
            uniform token physics:axis = "Z"
            rel physics:body0 = </vehicle/body>
            rel physics:body1 = </vehicle/rotor2>
            point3f physics:localPos0 = (-0.254, 0.4399, 0.03)
            point3f physics:localPos1 = (0, 0, 0)
        }
    }

    def Xform "rotor3" (
        apiSchemas = ["PhysicsMassAPI", "PhysicsRigidBodyAPI", "PhysxRigidBodyAPI"]
    )
    {
        float3 physics:diagonalInertia = (0.00000975, 0.000273, 0.000274)
        bool physics:kinematicEnabled = 0
        float physics:mass = 0.05
        bool physics:rigidBodyEnabled = 1
        float physxRigidBody:angularDamping = 0
        float physxRigidBody:maxAngularVelocity = 10000
        float physxRigidBody:maxContactImpulse = 0.1
        quatf xformOp:orient = (1, 0, 0, 0)
        double3 xformOp:scale = (1, 1, 1)
        float3 xformOp:translate = (-0.508, 0, 0.03)
        uniform token[] xformOpOrder = ["xformOp:translate", "xformOp:orient", "xformOp:scale"]

        def Xform "propeller" (
            prepend references = @./propeller.usd@
        )
        {
            double3 xformOp:scale = (3, 3, 3)
            uniform token[] xformOpOrder = ["xformOp:translate", "xformOp:orient", "xformOp:scale"]
        }

        def PhysicsRevoluteJoint "rotor_4"
        {
            uniform token physics:axis = "Z"
            rel physics:body0 = </vehicle/body>
            rel physics:body1 = </vehicle/rotor3>
            point3f physics:localPos0 = (-0.508, 0, 0.03)
            point3f physics:localPos1 = (0, 0, 0)
        }
    }

    def Xform "rotor4" (
        apiSchemas = ["PhysicsMassAPI", "PhysicsRigidBodyAPI", "PhysxRigidBodyAPI"]
    )
    {
        float3 physics:diagonalInertia = (0.00000975, 0.000273, 0.000274)
        bool physics:kinematicEnabled = 0
        float physics:mass = 0.05
        bool physics:rigidBodyEnabled = 1
        float physxRigidBody:angularDamping = 0
        float physxRigidBody:maxAngularVelocity = 10000
        float physxRigidBody:maxContactImpulse = 0.1
        quatf xformOp:orient = (1, 0, 0, 0)
        double3 xformOp:scale = (1, 1, 1)
        float3 xformOp:translate = (-0.254, -0.4399, 0.03)
        uniform token[] xformOpOrder = ["xformOp:translate", "xformOp:orient", "xformOp:scale"]

        def Xform "propeller" (
            prepend references = @./propeller.usd@
        )
        {
            double3 xformOp:scale = (3, 3, 3)
            uniform token[] xformOpOrder = ["xformOp:translate", "xformOp:orient", "xformOp:scale"]
        }

        def PhysicsRevoluteJoint "rotor_5"
        {
            uniform token physics:axis = "Z"
            rel physics:body0 = </vehicle/body>
            rel physics:body1 = </vehicle/rotor4>
            point3f physics:localPos0 = (-0.254, -0.4399, 0.03)
            point3f physics:localPos1 = (0, 0, 0)
        }
    }

    def Xform "rotor5" (
        apiSchemas = ["PhysicsMassAPI", "PhysicsRigidBodyAPI", "PhysxRigidBodyAPI"]
    )
    {
        float3 physics:diagonalInertia = (0.00000975, 0.000273, 0.000274)
        bool physics:kinematicEnabled = 0
        float physics:mass = 0.05
        bool physics:rigidBodyEnabled = 1
        float physxRigidBody:angularDamping = 0
        float physxRigidBody:maxAngularVelocity = 10000
        float physxRigidBody:maxContactImpulse = 0.1
        quatf xformOp:orient = (1, 0, 0, 0)
        double3 xformOp:scale = (1, 1, 1)
        float3 xformOp:translate = (0.254, -0.4399, 0.03)
        uniform token[] xformOpOrder = ["xformOp:translate", "xformOp:orient", "xformOp:scale"]

        def Xform "propeller" (
            prepend references = @./propeller.usd@
        )
        {
            double3 xformOp:scale = (3, 3, 3)
            uniform token[] xformOpOrder = ["xformOp:translate", "xformOp:orient", "xformOp:scale"]
        }

        def PhysicsRevoluteJoint "rotor_6"
        {
            uniform token physics:axis = "Z"
            rel physics:body0 = </vehicle/body>
            rel physics:body1 = </vehicle/rotor5>
            point3f physics:localPos0 = (0.254, -0.4399, 0.03)
            point3f physics:localPos1 = (0, 0, 0)
        }
    }
}

